<mujoco model="double_pendulum">
    <compiler angle="radian" coordinate="global" inertiafromgeom="true"/>
    <option timestep="0.01" gravity="[0 0 -9.81]"/>
    <worldbody>
        <body name="base" pos="0 0 0">
            <joint name="joint1" type="hinge" axis="0 0 1"/>
            <geom name="base_geom" type="cylinder" pos="0 0 0" size=".1 .1 .05" rgba=".8 .6 .4 1"/>
            <body name="link1" pos="0.5 0 0">
                <joint name="joint2" type="hinge" axis="0 0 1"/>
                <geom name="link1_geom" type="cylinder" pos="0 0 0" size=".05 1 .05" rgba=".8 .6 .4 1" mass="1"/>
                <body name="link2" pos="0.5 0 0">
                    <geom name="link2_geom" type="cylinder" pos="0 0 0" size=".05 1 .05" rgba=".8 .6 .4 1" mass="1"/>
                </body>
            </body>
        </body>
    </worldbody>
    <actuator>
        <motor joint="joint1" ctrlrange="-1.0 1.0" ctrllimited="true"/>
        <motor joint="joint2" ctrlrange="-1.0 1.0" ctrllimited="true"/>
    </actuator>
</mujoco>